Workbook

Sheet Haushaltsbuch 25
A1: Haushaltsbuch
C3: Januar | D3: Februar | E3: März | F3: April | G3: Mai | H3: Juni | I3: Juli | J3: August | K3: September | L3: Oktober | M3: November | N3: Dezember | O3: Gesamt | P3: Durchschnitt
B4: Einnahmen
B5: Gehalt | C5: 2448.03 | D5: 2242.4 | E5: 2242.4 | F5: 2242.4 | G5: 2242.4 | H5: 2242.4 | I5: 2242.4 | J5: 2285.51 | K5: 2285.51 | L5: 2285.51 | M5: 2285.51 | N5: 2285.51 | O5: =SUM(C5:N5) -> 27329.98
B6: Aktien | C6: 204.08 | D6: 194.49 | E6: 199.79 | F6: 194.88 | G6: 200.35 | H6: 186.12 | I6: 199.01 | J6: 203.29
B7: Variable Einnahmen | C7: 335 | E7: =141.68 + 3094 +202.2 -> 3437.88 | F7: =44.99 + 62.93 -> 107.92 | H7: =150.05+24+265.97+298.89+1231.06 -> 1969.97 | I7: =49 -> 49 | J7: =85+238.37 -> 323.37 | K7: 2730
B8: Gesamt | C8: =SUM(C5:C7) -> 2987.11 | D8: =SUM(D5:D7) -> 2436.89 | E8: =SUM(E5:E7) -> 5880.07 | F8: =SUM(F5:F7) -> 2545.2 | G8: =SUM(G5:G7) -> 2442.75 | H8: =SUM(H5:H7) -> 4398.49 | I8: =SUM(I5:I7) -> 2490.41 | J8: =SUM(J5:J7) -> 2812.17 | ... N8: =SUM(N5:N7) -> 2285.51 | O8: =SUM(C8:N8) -> 37865.13 | P8: =SUM(C8:N8) /12 -> 3155.4275
B10: Sparen
B11: Monatlich zur Verfügung (70%) | C11: =(C8*70)/100 -> 2090.977 | D11: =(D8*70)/100 -> 1705.823 | E11: =(E8*70)/100 -> 4116.049 | F11: =(F8*70)/100 -> 1781.64 | G11: =(G8*70)/100 -> 1709.925 | H11: =(H8*70)/100 -> 3078.943 | I11: =(I8*70)/100 -> 1743.287 | J11: =(J8*70)/100 -> 1968.519 | ... N11: =(N8*70)/100 -> 1599.857
B12: Konto 20% | C12: =(C8*20)/100 -> 597.422 | D12: =(D8*20)/100 -> 487.378 | E12: =(E8*20)/100 -> 1176.014 | F12: =(F8*20)/100 -> 509.04 | G12: =(G8*20)/100 -> 488.55 | H12: =(H8*20)/100 -> 879.698 | I12: =(I8*20)/100 -> 498.082 | J12: =(J8*20)/100 -> 562.434 | ... N12: =(N8*20)/100 -> 457.102
B13: Investment 10% | C13: 250 | D13: =(D8*10)/100 -> 243.689 | E13: =(E8*10)/100 -> 588.007 | F13: =(F8*10)/100 -> 254.52 | G13: =(G8*10)/100 -> 244.275 | H13: =(H8*10)/100 -> 439.849 | I13: =(I8*10)/100 -> 249.041 | J13: =(J8*10)/100 -> 281.217 | K13: =(K8*10)/100 -> 501.551 | ... N13: =(N8*10)/100 -> 228.551
B15: Fix Kosten
B16: Wohnen | C16: =SUM(C17:C21) -> 785.9 | D16: =SUM(D17:D21) -> 840.98 | E16: =SUM(E17:E21) -> 1555.9 | F16: =SUM(F17:F21) -> 1555.9 | G16: =SUM(G17:G21) -> 1555.9 | H16: =SUM(H17:H21) -> 844.99 | I16: =SUM(I17:I21) -> 844.99 | J16: =SUM(J17:J21) -> 844.99 | ... N16: =SUM(N17:N21) -> 800 | O16: =SUM(C16:N16) -> 12029.55
B17: Miete | C17: 680.91 | D17: 680.91 | E17: =650.91 +800 -> 1450.91 | F17: =650.91 +800 -> 1450.91 | G17: =650.91 +800 -> 1450.91 | H17: 800 | I17: 800 | J17: 800 | K17: 800 | L17: 800 | M17: 800 | N17: 800
B18: Strom | C18: 60 | D18: 60 | E18: 60 | F18: 60 | G18: 60 | H18: 0 | I18: 0 | J18: 0 | K18: 0 | L18: 0 | M18: 0 | N18: 0
B19: Internet | C19: 44.99 | D19: 44.99 | E19: 44.99 | F19: 44.99 | G19: 44.99 | H19: 44.99 | I19: 44.99 | J19: 44.99 | K19: 0 | L19: 0 | M19: 0 | N19: 0
B20: Hausratversicherung | C20: 0 | D20: 0 | E20: 0 | F20: 0 | G20: 0 | H20: 0 | I20: 0 | J20: 0 | K20: 0 | L20: 0 | M20: 0 | N20: 0
B21: GEZ | C21: 0 | D21: 55.08 | E21: 0 | F21: 0 | G21: 0 | H21: 0 | I21: 0 | J21: 0 | K21: 0 | L21: 0 | M21: 0 | N21: 0
B22: Versicherungen | C22: =SUM(C23:C24) -> 0 | D22: =SUM(D23:D24) -> 0 | E22: =SUM(E23:E24) -> 0 | F22: =SUM(F23:F24) -> 0 | G22: =SUM(G23:G24) -> 0 | H22: =SUM(H23:H24) -> 0 | I22: =SUM(I23:I24) -> 0 | J22: =SUM(J23:J24) -> 13.6 | ... N22: =SUM(N23:N24) -> 80.56 | O22: =SUM(C22:N22) -> 144.38
B23: Auslandskrankenversicherung | C23: 0 | D23: 0 | E23: 0 | F23: 0 | G23: 0 | H23: 0 | I23: 0 | J23: 0 | K23: 50.22 | L23: 0 | M23: 0 | N23: 80.56
B24: Haftpflichtversicherung | C24: 0 | D24: 0 | E24: 0 | F24: 0 | G24: 0 | H24: 0 | I24: 0 | J24: 13.6 | K24: 0 | L24: 0 | M24: 0 | N24: 0
B25: Sport | C25: =SUM(C26:C27) -> 37.9 | D25: =SUM(D26:D27) -> 37.9 | E25: =SUM(E26:E27) -> 37.9 | F25: =SUM(F26:F27) -> 37.9 | G25: =SUM(G26:G27) -> 37.9 | H25: =SUM(H26:H27) -> 37.9 | I25: =SUM(I26:I27) -> 37.9 | J25: =SUM(J26:J27) -> 37.9 | ... N25: =SUM(N26:N27) -> 37.9 | O25: =SUM(C25:N25) -> 574.8
B26: Badminton | C26: 0 | D26: 0 | E26: 0 | F26: 0 | G26: 0 | H26: 0 | I26: 0 | J26: 0 | K26: 0 | L26: 120 | M26: 0 | N26: 0
B27: Cleverfit | C27: 37.9 | D27: 37.9 | E27: 37.9 | F27: 37.9 | G27: 37.9 | H27: 37.9 | I27: 37.9 | J27: 37.9 | K27: 37.9 | L27: 37.9 | M27: 37.9 | N27: 37.9
B28: Deutscher Alpen Verein | C28: 96 | D28: 0 | E28: 0 | F28: 0 | G28: 0 | H28: 0 | I28: 0 | J28: 0 | K28: 0 | L28: 0 | M28: 0 | N28: 0
B29: Auto | C29: =SUM(C30:C32) -> 143 | D29: =SUM(D30:D32) -> 700.06 | E29: =SUM(E30:E32) -> 0 | F29: =SUM(F30:F32) -> 0 | G29: =SUM(G30:G32) -> 0 | H29: =SUM(H30:H32) -> 0 | I29: =SUM(I30:I32) -> 0 | J29: =SUM(J30:J32) -> 0 | ... N29: =SUM(N30:N32) -> 0
B30: Versicherung | C30: 0 | D30: 700.06 | E30: 0 | F30: 0 | G30: 0 | H30: 0 | I30: 0 | J30: 0 | K30: 0 | L30: 0 | M30: 0 | N30: 0
B31: ADAC | C31: 79 | D31: 0 | E31: 0 | F31: 0 | G31: 0 | H31: 0 | I31: 0 | J31: 0 | K31: 0 | L31: 0 | M31: 0 | N31: 0
B32: Steuern | C32: 64 | D32: 0 | E32: 0 | F32: 0 | G32: 0 | H32: 0 | I32: 0 | J32: 0 | K32: 0 | L32: 0 | M32: 0 | N32: 0
B33: Sonstige Verträge | C33: =SUM(C34:C40) -> 84.36 | D33: =SUM(D34:D40) -> 88.85 | E33: =SUM(E34:E40) -> 84.36 | F33: =SUM(F34:F40) -> 84.36 | G33: =SUM(G34:G40) -> 84.36 | H33: =SUM(H34:H40) -> 84.36 | I33: =SUM(I34:I40) -> 84.36 | J33: =SUM(J34:J40) -> 84.36 | ... N33: =SUM(N34:N40) -> 74.36 | O33: =SUM(C33:N33) -> 976.81
B34: Apple Musik, Cloud | C34: 5.5 | D34: 5.5 | E34: 5.5 | F34: 5.5 | G34: 5.5 | H34: 5.5 | I34: 5.5 | J34: 5.5 | K34: 5.5 | L34: 5.5 | M34: 5.5 | N34: 5.5
B35: Amazon | C35: =8.99+2.99 -> 11.98 | D35: =8.99+2.99 -> 11.98 | E35: =8.99+2.99 -> 11.98 | F35: =8.99+2.99 -> 11.98 | G35: =8.99+2.99 -> 11.98 | H35: =8.99+2.99 -> 11.98 | I35: =8.99+2.99 -> 11.98 | J35: =8.99+2.99 -> 11.98 | ... N35: =8.99+2.99 -> 11.98
B36: Handy | C36: 19.99 | D36: 19.99 | E36: 19.99 | F36: 19.99 | G36: 19.99 | H36: 19.99 | I36: 19.99 | J36: 19.99 | K36: 9.99 | L36: 9.99 | M36: 9.99 | N36: 9.99
B37: Netflix | C37: 13.99 | D37: 18.48 | E37: 13.99 | F37: 13.99 | G37: 13.99 | H37: 13.99 | I37: 13.99 | J37: 13.99 | K37: 13.99 | L37: 13.99 | M37: 13.99 | N37: 13.99
B38: Claude AI | C38: 21.42 | D38: 21.42 | E38: 21.42 | F38: 21.42 | G38: 21.42 | H38: 21.42 | I38: 21.42 | J38: 21.42 | K38: 21.42 | L38: 21.42 | M38: 21.42 | N38: 21.42
B39: Ing Diba | C39: 1.49 | D39: 1.49 | E39: 1.49 | F39: 1.49 | G39: 1.49 | H39: 1.49 | I39: 1.49 | J39: 1.49 | K39: 1.49 | L39: 1.49 | M39: 1.49 | N39: 1.49
B40: Dazn | C40: 9.99 | D40: 9.99 | E40: 9.99 | F40: 9.99 | G40: 9.99 | H40: 9.99 | I40: 9.99 | J40: 9.99 | K40: 9.99 | L40: 9.99 | M40: 9.99 | N40: 9.99
B41: Gesamt | C41: =SUM(C16+C22+C25+C33+C29) -> 1051.16 | D41: =SUM(D16+D22+D25+D33+D29) -> 1667.79 | E41: =SUM(E16+E22+E25+E33) -> 1678.16 | F41: =SUM(F16+F22+F25+F33) -> 1678.16 | G41: =SUM(G16+G22+G25+G33) -> 1678.16 | H41: =SUM(H16+H22+H25+H33) -> 967.25 | I41: =SUM(I16+I22+I25+I33) -> 967.25 | J41: =SUM(J16+J22+J25+J33) -> 980.85 | K41: =SUM(K16+K22+K25+K33) -> 962.48 | L41: =SUM(L16+L22+L25+L33) -> 1032.26 | ... N41: =SUM(N16+N22+N25+N33) -> 992.82 | O41: =SUM(C41:N41) -> 14568.6
B43: Variable Kosten
B44: Lebensmittel | C44: =Januar!B1 -> 451.605 | D44: =Februar!B1 -> 617.26 | E44: ='März'!B1 -> 596.13 | F44: =April!B1 -> 359.3 | G44: =Mai!B1 -> 184.26 | H44: =Juni!B1 -> 221.124 | I44: =Juli!B1 -> 363.51 | J44: =August!B1 -> 157.13 | K44: =September!B1 -> 0 | L44: =Oktober!B1 -> 0 | M44: =November!B1 -> 0 | N44: =Dezember!B1 -> 0
...

Sheet Januar
A1: Lebensmittel | B1: =SUM(B3:B62) -> 451.605 | D1: Auto | E1: =SUM(E3:E62) -> 108.45 | G1: Kleidung | H1: =SUM(H3:H62) -> 0 | J1: Sonstiges | K1: =SUM(K3:K62) -> 487.37 | M1: Katzen | N1: =SUM(N3:N62) -> 0
A2: Name | B2: Ausgabe | D2: Name | E2: Ausgabe | G2: Name | H2: Ausgabe | J2: Name | K2: Ausgabe | M2: Name | N2: Ausgabe
A3: Kaufland | B3: 12.54 | D3: Tanken | E3: 37.65
A4: Rossman | B4: 20.74 | D4: Tanken | E4: 69.6 | J4: Relai | K4: 50
A5: Kaufland | B5: 5.4 | D5: Easy Park | E5: 1.2 | J5: Schwimmen | K5: 4.5
A6: Bäcker | B6: 3.15 | J6: Kissen | K6: 10.95
A7: Rewe | B7: =90.19/2 -> 45.095 | J7: Oma Handy | K7: 20
A8: Rewe | B8: 5.36 | J8: Urlaub ESG | K8: 92.5
A9: Kaffe | B9: 1.5 | J9: Supps | K9: 9.7
A10: Baude | B10: =36.2/2 -> 18.1 | J10: WoW | K10: 60
A11: ElbFlorenz | B11: =54.5/2 -> 27.25 | J11: Hanseatic Bank | K11: 239.72
A12: Lidl Bad Schandau | B12: =34.62 -> 34.62
A13: Essen Total | B13: =10.49/2 -> 5.245
A14: Cafe | B14: 3.5
A15: Kaufland | B15: 9.7
A16: kaufland | B16: 5.58
A17: kaufland | B17: 11.89
A18: Rewe | B18: =54.37 -> 54.37
A19: Kaufland | B19: 23.87
A20: Rewe | B20: =80.81/2 -> 40.405
A21: Bäcker | B21: 5.58
A22: Kaufland | B22: 4.18
A23: Rewe | B23: 6.57
A24: Kaufland | B24: 4.11
A25: Papa Kakao | B25: 1
A26: Kaufland | B26: 10.19
A27: Kaufland | B27: 21.48
A28: Rewe | B28: =81.58/2 -> 40.79
A29: Kaufland | B29: 4
A30: Kaufland | B30: 3.98
A31: Kaufland | B31: 13.67
A32: Edeka | B32: 7.74

Sheet Februar
A1: Lebensmittel | B1: =SUM(B3:B62) -> 617.26 | D1: Auto | E1: =SUM(E3:E62) -> 200.95 | G1: Kleidung | H1: =SUM(H3:H62) -> 0 | J1: Sonstiges | K1: =SUM(K3:K62) -> 220.43 | M1: Katzen | N1: =SUM(N62) -> 0
A2: Name | B2: Ausgabe | D2: Name | E2: Ausgabe | G2: Name | H2: Ausgabe | J2: Name | K2: Ausgabe | M2: Name | N2: Ausgabe
A3: Rewe | B3: =81.57 /2 -> 40.785 | D3: Easy Park | E3: 1.2 | J3: Relai | K3: 50
A4: Kaufland | B4: 3.98 | D4: Tanken | E4: 67.26 | J4: BattleNet | K4: 60
A5: Bäcker | B5: 5.58 | D5: Tanken | E5: 59.95 | J5: BrokenPass | K5: 12.95
A6: Kaufland | B6: 4 | D6: Parken | E6: 14 | J6: Friseur | K6: 20
A7: Theo Automat | B7: 1 | D7: Tanken | E7: 58.54 | J7: Besaitung | K7: 12
A8: Kaufland | B8: 21.48 | J8: BVG | K8: 4
A9: Kaufland | B9: 10.19 | J9: BVG | K9: 4
A10: Rewe | B10: 6.57 | J10: Roit | K10: 4.99
A11: Kaufland | B11: 4.11 | J11: OL | K11: 5.5
A12: Kaufland | B12: 4.18 | J12: Kissen | K12: 24.91
A13: Döner | B13: 11 | J13: Bezug | K13: 10.99
A14: Rewe | B14: 16.63 | J14: Post | K14: 4.19
A15: Edeka | B15: 4.83 | J15: schwimmen | K15: 4.5
A16: Rewe | B16: =91.92/2 -> 45.96 | J16: PUG Kauf | K16: 2.4
A17: Kaufland | B17: 7.98
A18: Bäcker | B18: 3.88
A19: Backer | B19: 4.7
A20: Rewe | B20: 20.39
A21: Rewe | B21: 9.36
A22: Kaufland | B22: 3.59
A23: Bäcker | B23: 6.75
A24: Kaufland | B24: 9.19
A25: Globus | B25: 32.91
A26: Kaufland | B26: 6.78
A27: Rewe | B27: =93.91/2 -> 46.955
A28: Kaufland | B28: 4.68
A29: Kaufland | B29: 5.73
A30: Barb | B30: 14.97
A31: Demirel | B31: 6.5
A32: Automat | B32: 1.3
A33: Bäcker | B33: 6.65
A34: Annika Restaurant | B34: 38.01
A35: Kaufland | B35: 9.86
A36: Dominos | B36: 23.24
A37: Kaufland | B37: 3.78
A38: Kaufland | B38: 11.74
A39: Rewe | B39: =107.38 / 2 -> 53.69
A40: Broken | B40: 31.1
...

Sheet März
A1: Lebensmittel | B1: =SUM(B3:B62) -> 596.13 | D1: Auto | E1: =SUM(E3:E62) -> 158.85 | G1: Kleidung | H1: =SUM(H3:H62) -> 0 | J1: Sonstiges | K1: =SUM(K3:K62) -> 3003.18 | M1: Katzen | N1: =SUM(N62) -> 0
A2: Name | B2: Ausgabe | D2: Name | E2: Ausgabe | G2: Name | H2: Ausgabe | J2: Name | K2: Ausgabe | M2: Name | N2: Ausgabe
A3: Kaufland | B3: 2.88 | D3: Tanken | E3: 77.46 | J3: Schwimmbrille | K3: 22.09
A4: Rewe | B4: =97.14/2 -> 48.57 | D4: Easy Park | E4: 1.3 | J4: Canvas | K4: 12
A5: QLF | B5: 69.04 | D5: Easy Park | E5: 2.05 | J5: Globus | K5: 33.06
A6: Rossmann | B6: 3.79 | D6: Wäsche | E6: 15.99 | J6: Relai | K6: 50
A7: Kaufland | B7: 5.03 | D7: Total | E7: 6.8 | J7: Aral | K7: 5.99
A8: Netto | B8: 13.98 | D8: Tanken | E8: 55.25 | J8: Schwimmen | K8: 4.5
A9: Dominos | B9: 27.87 | J9: Extra Konto | K9: 1000
A10: Kaufland | B10: 14.77 | J10: David Yazio | K10: 10
A11: Rewe | B11: 21.61 | J11: Friseur | K11: 20
A12: Bäcker | B12: 6.88 | J12: Schwimmen | K12: 4.5
A13: Dominos | B13: 25 | J13: GoPro Halterung | K13: 14.39
A14: Rewe | B14: =85.86 / 2 -> 42.93 | J14: Wohnung | K14: 420.2
A15: Kaufland | B15: 8.07 | J15: Schwimmen | K15: 4.5
A16: Kaufland | B16: 4.29 | J16: Buch | K16: 22.95
A17: Dominos | B17: 15.49 | J17: Wäschekorb | K17: 29.99
A18: Rewe | B18: 1.29 | J18: Rolladen | K18: 66.75
A19: Kaufland | B19: 12.4 | J19: Miete Wohnung | K19: 800
A20: Rewe | B20: 0.42 | J20: Globus | K20: 63.65
A21: Dominos | B21: 15.49 | J21: Radhose | K21: 26.95
A22: Bäcker | B22: 9.5 | J22: Schränke | K22: 258.24
A23: Kaufland | B23: 9.15 | J23: BVG | K23: 4
A24: Lidl | B24: 2.97 | J24: Oma Handy | K24: 20
A25: Bauer | B25: 2.5 | J25: OL | K25: 13
A26: Bäcker | B26: 3.15 | J26: Müller | K26: 46.42
A27: Dominos | B27: 23.42 | J27: Relai | K27: 50
A28: Kaufland | B28: 10.59
A29: Kaufland | B29: 6.87
A30: Döner | B30: 16
A31: Aldi | B31: 1.68
A32: Kaufland | B32: 1.56
A33: Kaufland | B33: 6.71
A34: Dominos | B34: 32.48
A35: Brammibals | B35: 12.3
A36: QLF | B36: 54.18
A37: Rossmann | B37: 8.53
A38: Bauernmarkt Kells | B38: 48.75
A39: Bäcker | B39: 5.99

Sheet April
A1: Lebensmittel | B1: =SUM(B3:B62) -> 359.3 | D1: Auto | E1: =SUM(E3:E62) -> 119.27 | G1: Kleidung | H1: =SUM(H3:H62) -> 0 | J1: Sonstiges | K1: =SUM(K3:K62) -> 1199.26 | M1: Katzen | N1: =SUM(N3:N62) -> 0
A2: Name | B2: Ausgabe | D2: Name | E2: Ausgabe | G2: Name | H2: Ausgabe | J2: Name | K2: Ausgabe | M2: Name | N2: Ausgabe
A3: Rossmann | B3: 8.53 | D3: Tanken | E3: 67.56 | J3: Supps | K3: 54.18
A4: Kells Bauernmarkt | B4: 48.75 | D4: Parken | E4: 1 | J4: Schrank | K4: 109.64
A5: Kaufland | B5: 8.79 | D5: Tanken | E5: 50.71 | J5: Fahrrad | K5: 56.95
A6: WrieBa | B6: 7.65 | J6: Canva | K6: 12
A7: WrieBa | B7: 5.6 | J7: Globus | K7: 44.54
A8: Bäcker | B8: 14.44 | J8: Bargeld | K8: 150
A9: Ikea HotDog | B9: 2.5 | J9: Luisa | K9: 14.34
A10: WrieBa | B10: 4.25 | J10: Schloss | K10: 7.29
A11: Pizza Dorado | B11: 22.2 | J11: Fahrrad Tasche | K11: 43.99
A12: Döner | B12: 16 | J12: Rollo | K12: 21.35
A13: WrieBa | B13: 9.85 | J13: Kettenhalter | K13: 4.99
A14: Kaufland | B14: 12.52 | J14: Buch | K14: 15.76
A15: Burger | B15: 27.4 | J15: Film | K15: 3.99
A16: Kaufland | B16: 12.52 | J16: Supps | K16: 95.96
A17: Kaufland | B17: 3.88 | J17: Schrank | K17: 104.26
... A22: Kaufland | B22: 11.58 | J22: Tefal | K22: 28.23
A23: Kaufland | B23: 0.78 | J23: Socken | K23: =10.99*2 -> 21.98
A24: Kaufland | B24: 1.99 | J24: Mauspad | K24: 13.95
A25: Hilde und Kurt | B25: 15.77 | J25: Usb Hub | K25: 7.97
A26: Hilde und Kurt | B26: 8.58 | J26: Usb Verlängerung | K26: 5.97
A27: Dominos | B27: 23.24 | J27: Verlängerungskabel | K27: 15.38
A28: Bäcker | B28: 4.58 | J28: Hausschuhe | K28: 26.99
A29: Ikea HotDog | B29: 3 | J29: Lampe | K29: 11.19
A30: Kaufland | B30: 8.82 | J30: Brett | K30: 8.99
A31: Kaufland | B31: 4.82 | J31: Abzieher Dusche | K31: 19.49
A32: Pizza Dorado | B32: 22.87 | J32: Globus | K32: 71.04
A33: Kaufland | B33: 5.28 | J33: Globus | K33: =10.18+23.98+2.69+29.99 -> 66.84
A34: Kaufland | B34: 10.84

Sheet Mai
A1: Lebensmittel | B1: =SUM(B3:B62) -> 184.26 | D1: Auto | E1: =SUM(E3:E62) -> 40 | G1: Kleidung | H1: =SUM(H3:H62) -> 0 | J1: Sonstiges | K1: =SUM(K3:K62) -> 463.11 | M1: Katzen | N1: =SUM(N3:N62) -> 0
A2: Name | B2: Ausgabe | D2: Name | E2: Ausgabe | G2: Name | H2: Ausgabe | J2: Name | K2: Ausgabe | M2: Name | N2: Ausgabe
A3: Poco Locco | B3: 80 | D3: Blitzer | E3: 40 | J3: Frank Geschenk | K3: 34.03
A4: Mueller | B4: 8.76 | J4: Canva | K4: 12
A5: Kaufland | B5: 34.03 | J5: ETF | K5: 200
A6: Müller | B6: 8.76 | J6: Relai | K6: 50
A7: Kaufland | B7: 3.74 | J7: Roit | K7: 10.99
A8: Kaufland | B8: 9.38 | J8: BVG | K8: 8
A9: Kaufland | B9: 11.83 | J9: Ionos | K9: 1
A10: Dominos | B10: 23.24 | J10: Kopfhörer | K10: 118.15
A11: Lidl | B11: 2.98 | J11: FahrradCreme | K11: 11.99
A12: Rewe | B12: 1.54 | J12: Amali Geschenk | K12: 16.95

Sheet Juni
A1: Lebensmittel | B1: =SUM(B3:B62) -> 221.124 | D1: Auto | E1: =SUM(E3:E62) -> 109.26 | G1: Kleidung | H1: =SUM(H3:H62) -> 0 | J1: Sonstiges | K1: =SUM(K3:K62) -> 2757.68 | M1: Katzen | N1: =SUM(N3:N62) -> 0
A2: Name | B2: Ausgabe | D2: Name | E2: Ausgabe | G2: Name | H2: Ausgabe | J2: Name | K2: Ausgabe | M2: Name | N2: Ausgabe
A3: Dorado | B3: 50.4 | D3: Tank | E3: 53.08 | J3: Bargeld | K3: 50
A4: Rewe | B4: 5.17 | E4: 56.18 | J4: LinkedIn | K4: 118.99
A5: Bäcker | B5: 5.09 | J5: Amazon | K5: 82.19
A6: Kaufland | B6: 6.7 | J6: amazon | K6: 76.98
B7: 2.48 | J7: Amazon | K7: 39
B8: 1.58 | J8: Amazon | K8: 23.99
B9: 6.74 | J9: Rossman | K9: 2.3
B10: 6 | J10: Roit | K10: 10.99
B11: 7.36 | J11: Urlaub | K11: 18.52
B12: 10.8 | J12: Obi | K12: 7.79
B13: 2 | J13: Laptop | K13: 1146.98
B14: 5.09 | K14: 16.13
B15: 2.78 | K15: 9.48
B16: 12.34 | J16: Amazon | K16: 24
B17: 0.98 | K17: 0.99
B18: 3.33 | K18: 12.88
B19: 6.46 | K19: 9.99
B20: 6.2 | K20: 14.99
B21: 7.86 | K21: 88.99
B22: 6.01 | K22: 169.96
B23: 6.08 | K23: 10.99
B24: 1.65 | K24: 6.05
B25: 5.59 | K25: 60
B26: 19.61 | K26: 6.07
B27: 2.434 | K27: 109.15
B28: 6 | K28: 87.1
... B30: 21.51 | K30: 24.21
K31: 2.99
K32: 15.99
K33: 500

Sheet Juli
A1: Lebensmittel | B1: =SUM(B3:B62) -> 363.51 | D1: Auto | E1: =SUM(E3:E62) -> 156.44 | G1: Kleidung | H1: =SUM(H3:H62) -> 0 | J1: Sonstiges | K1: =SUM(K3:K62) -> 1965.62 | M1: Katzen | N1: =SUM(N62) -> 0
A2: Name | B2: Ausgabe | D2: Name | E2: Ausgabe | G2: Name | H2: Ausgabe | J2: Name | K2: Ausgabe | M2: Name | N2: Ausgabe
B3: 5.33 | E3: 56.69 | K3: 26.95
B4: 39.8 | E4: 69.75 | K4: 59.49
B5: 3.48 | E5: 30 | K5: 28.19
B6: 7.18 | K6: 50
B7: 9.17 | K7: 6.95
B8: 5.45 | K8: 200
B9: 2.93 | K9: 21.2
B10: 4.99 | K10: 21.99
B11: 6.33 | K11: 4.99
B12: 4.95 | K12: 24.24
B13: 5.09 | K13: 69.9
B14: 4.62 | K14: 50
B15: 4.08 | K15: 6.07
B16: 16 | K16: 1
B17: 29 | K17: 103
... B50: 2.9 | K50: 9.71
K51: 0.18
K52: 77.8
K53: 25.4
K54: 13.5
K55: 10
K56: 5

Sheet August
A1: Lebensmittel | B1: =SUM(B3:B62) -> 157.13 | D1: Auto | E1: =SUM(E3:E62) -> 181.07 | G1: Kleidung | H1: =SUM(H3:H62) -> 0 | J1: Sonstiges | K1: =SUM(K3:K62) -> 1861.22 | M1: Katzen | N1: =SUM(N62) -> 0
A2: Name | B2: Ausgabe | D2: Name | E2: Ausgabe | G2: Name | H2: Ausgabe | J2: Name | K2: Ausgabe | M2: Name | N2: Ausgabe
A3: Rewe | B3: 3.24 | D3: Tanken | E3: 57.23 | K3: 524.74
A4: Müller | B4: 4.99 | D4: Tanken | E4: 32.71 | K4: 50
A5: Rewe | B5: 3.18 | D5: Tanken +Snack | E5: 91.13 | J5: Urlaub | K5: 269.59
A6: Bäcker | B6: 7.28 | J6: Bar | K6: 50
A7: Bäcker | B7: 6.6 | J7: Globus | K7: 17.86
A8: Rewe | B8: 16.71 | J8: Sum | K8: 40.46
A9: Kaufland | B9: 2.09 | J9: Amazon | K9: 7.36
A10: Müller | B10: 12.34 | J10: Amazon | K10: 18.06
A11: Snack | B11: 3.93 | J11: Amazon | K11: 10.99
A12: Kaufland | B12: 2.09 | J12: Sum | K12: 1
A13: Kaufland | B13: 3.68 | J13: Maurice Geschenk | K13: 49.95
A14: Bäcker | B14: 3.1 | J14: Amazon | K14: 8.95
A15: Kaufland | B15: 6.8 | J15: Amazon | K15: 16.58
A16: Rewe | B16: 8 | J16: Claude | K16: 21.42
A17: Steinecke | B17: 3 | J17: Canva | K17: 12
... A28: Rewe | B28: 16.9 | J28: Amazon | K28: 2.99
J29: Amazon | K29: 13.9
J30: Inons | K30: 1
J31: PayPal | K31: 35
J32: PayPal | K32: 4.99
J33: Tornado | K33: 17.74
J34: Schlauch | K34: 10.33

Sheet September
A1: Lebensmittel | B1: =SUM(B3:B62) -> 0 | D1: Auto | E1: =SUM(E3:E62) -> 0 | G1: Kleidung | H1: =SUM(H3:H62) -> 0 | J1: Sonstiges | K1: =SUM(K3:K62) -> 1315.13 | M1: Katzen | N1: =SUM(N62) -> 0
A2: Name | B2: Ausgabe | D2: Name | E2: Ausgabe | G2: Name | H2: Ausgabe | J2: Name | K2: Ausgabe | M2: Name | N2: Ausgabe
J3: PowerBank | K3: 29.99
J4: Lampe vorne | K4: 75.99
J5: Cyclite | K5: 119.9
J6: Castelli | K6: 197.5
J7: Rücklicht | K7: 139.9
J8: Kreditkarte | K8: 578.99
J9: Mountain Squad | K9: 172.86

Sheet Oktober
A1: Lebensmittel | B1: =SUM(B3:B62) -> 0 | D1: Auto | E1: =SUM(E3:E62) -> 0 | G1: Kleidung | H1: =SUM(H3:H62) -> 0 | J1: Sonstiges | K1: =SUM(K3:K62) -> 0 | M1: Katzen | N1: =SUM(N62) -> 0
A2: Name | B2: Ausgabe | D2: Name | E2: Ausgabe | G2: Name | H2: Ausgabe | J2: Name | K2: Ausgabe | M2: Name | N2: Ausgabe

Sheet November
A1: Lebensmittel | B1: =SUM(B3:B62) -> 0 | D1: Auto | E1: =SUM(E3:E62) -> 0 | G1: Kleidung | H1: =SUM(H3:H62) -> 0 | J1: Sonstiges | K1: =SUM(K3:K62) -> 0 | M1: Katzen | N1: =SUM(N62) -> 0
A2: Name | B2: Ausgabe | D2: Name | E2: Ausgabe | G2: Name | H2: Ausgabe | J2: Name | K2: Ausgabe | M2: Name | N2: Ausgabe

Sheet Dezember
A1: Lebensmittel | B1: =SUM(B3:B62) -> 0 | D1: Auto | E1: =SUM(E3:E62) -> 0 | G1: Kleidung | H1: =SUM(H3:H62) -> 0 | J1: Sonstiges | K1: =SUM(K3:K62) -> 0 | M1: Katzen | N1: =SUM(N62) -> 0
A2: Name | B2: Ausgabe | D2: Name | E2: Ausgabe | G2: Name | H2: Ausgabe | J2: Name | K2: Ausgabe | M2: Name | N2: Ausgabe
